Workbook

Sheet GSTR1 Invoices
A1: If you are a new user then please read through sheet "Explanation of GSTR1 Invoices"
A2: *Invoice details (Linked Invoice Number & Date in case fo Credit/Debit Notes) | F2: *This is the destination of the product, typically the state of your customer | G2: *Provide these details for HSN summary under GST Return flow | O2: Tax details (Invoices should have either CGST &CGST or IGST value based on Place of Supply) | AA2: *Required in case of Bill of Supply. | AC2: *Required incase of Export of Goods | AN2: *Required in case this invoice is filed as a part of previous return period. | AP2: *Required incase of Amendment of Invoice | AV2: *Required if advance receipts are adjusted against invoices raised. | AY2: *Enter total invoice value here. If you have more than one line in the invoice, repeat the same value for every line. | AZ2: Optional Custom fields (Additionally voucher modified date & created by also supported, refer explanation) | BC2: Additional doc headers from ERP (New) | BF2: Additional line item details from ERP (Additionally we support tax code, GL code fields as well refer explanation for the same)
A3: Document Type Code | B3: Document Date* | C3: Document Number* | D3: Recipient Billing Name | E3: Recipient Billing GSTIN | F3: Place of Supply | G3: Is the item a GOOD (G) or SERVICE (S) | H3: Item Description | I3: HSN or SAC code | J3: Quantity | K3: Item Unit of Measurement | L3: Item Price | M3: Item Discount Amount | N3: Item Taxable Value* | O3: GST Rate | P3: CGST Rate | Q3: CGST Amount | R3: SGST Rate | S3: SGST Amount | T3: IGST Rate | U3: IGST Amount | V3: CESS Rate | W3: CESS Amount | X3: Reason for issuing CDN | Y3: Is this note for a Pre-GST Invoice? | Z3: Is this a Bill of Supply | AA3: Is this a Nil Rated/Exempt/NonGST item? | AB3: Is Reverse Charge Applicable? | AC3: Type of Export | AD3: Shipping Port Code - Export | AE3: Shipping Bill Number - Export | AF3: Shipping Bill Date - Export | AG3: Has GST/IDT TDS been deducted | AH3: My GSTIN | AI3: Recipient Billing Address | AJ3: Recipient Billing City | AK3: Recipient Billing State | AL3: Is this document cancelled? | AM3: Is the customer a Composition dealer or UIN registered? | AN3: Return Filing Month | AO3: Return Filing Quarter | AP3: Original Document Date (In case of amendment) | AQ3: Original Document Number (In case of amendment) | AR3: Original Customer Billing GSTIN (In case of amendment) | AS3: Special validations (For Multiple amendments, B2C to B2B conversion, etc.) | AT3: GSTIN of Ecommerce Marketplace | AU3: Applicable % of Tax Rate | AV3: Date of Linked Advance Receipt | AW3: Voucher Number of Linked Advance Receipt | AX3: Adjustment Amount of the Linked Advance Receipt | AY3: Total Document Value | AZ3: Voucher Number | BA3: Voucher Date | BB3: Voucher Created Date | BC3: ERP Source System | BD3: ERP Company Code | BE3: Customer Code | BF3: ERP Voucher Type | BG3: ERP Business Place | BH3: ERP Plant Code | BI3: ERP Profit Center | BJ3: Item Material Code | BK3: Other Charges (Document Level) | BL3: Linked Invoice Number (Filled In case of CDN) | BM3: Linked Invoice Date (Filled In case of CDN) | BN3: Linked Customer Billing GSTIN (Filled In case of CDN) | BO3: Which type of Invoice is this note linked to? | BP3: Supplier Legal Name | BQ3: Supplies u/s 9(5) | BR3: E-Com Supplier GSTIN | BS3: Original Return Filing Month | BT3: Original GSTIN of Ecommerce Marketplace | BU3: Deleted | BV3: Branch Name | BW3: Return Type | BX3: Sub Type

Sheet  Explanation of GSTR1 Invoices
A1: Field Name | B1: Is this field mandatory ? | C1: Description | D1: Field Specification | E1: Sample Values | F1: Additional Information
A2: Document Type Code | B2: Optional | C2: Identifies the type of documents (Invoice, Credit Note, Debit Note, Advance, Advance Adjustment) | E2: Invoice
A3: Supply Type Code | B3: Optional | C3: Identifies the type of Invoice (B2B,B2C,SEZ with payment etc) | E3: B2B
A4: Document Date | B4: Yes | C4: Document Date | D4: String (DD-MM-YYYY) | E4: 42939
A5: Document Number | B5: Yes | C5: Document Number | D5: Alphanumeric (Max length:16) | E5: INV8400 | F5: a consecutive serial number not exceeding sixteen characters, in one or multiple series, containing alphabets or numerals or special characters hyphen or dash and slash symbolised as “-” and “/” respectively, and any combination thereof, unique for a financial year;
A6: Recipient Billing Name | B6: Optional | C6: Customer Billing Name | D6: String (Max length:90) | E6: Iyer Furnitures Ltd. | F6: In case you don't have vendor name information (for example in case of unregistered purchases) then put any default dummy name for vendor name
A7: Recipient Billing GSTIN | B7: Yes for B2B | C7: GSTIN/UID of the Recipient | D7: Alphanumeric with 15 characters | E7: 06ADECO9084R5Z4
A8: Place of Supply | B8: Yes | C8: Place of supply state code (Refer to sheet name "State Code" defintion) | D8: String(Max length:2) | E8: 01-Jammu & Kashmir | F8: Refer to sheet name "State Code" defintion
A9: Is the item a GOOD (G) or SERVICE (S) | B9: Yes | C9: Identifier if Goods or Services | D9: One Character (G for Goods, S for services) | E9: G
A10: Item Description | B10: No | C10: Description of the item | D10: String (Max length:180) | E10: FabDecor Sofa Set Standard 1631
A11: HSN or SAC code | B11: Yes subject to the following condition from the government It will be mandatory to report HSN code at two digits level for taxpayers having annual turnover in the preceding year above Rs. 1.50 Cr but upto Rs. 5.00 Cr and at four digits level for taxpayers having annual turnover above Rs. 5.00 Cr | C11: HSN or SAC of Goods or Services as per Invoice line items | D11: Alphanumeric (Max length:10) | E11: 19059020 | F11: It will be mandatory to report HSN code at two digits level for taxpayers having annual turnover in the preceding year above Rs. 1.50 Cr but upto Rs. 5.00 Cr and at four digits level for taxpayers having annual turnover above Rs. 5.00 Cr
A12: Quantity | B12: Yes in case of Goods | C12: Quantity of Item | D12: Decimal(15, 2) | E12: 2
A13: Item Unit of Measurement | B13: Yes in case of Goods | C13: Unit of Measurement | D13: String (Max length:20) | E13: BAG-BAGS
A14: Item Price | B14: Yes in case of Goods | C14: Item Price | D14: Decimal(15, 2) | E14: 18000
A15: Item Discount Amount | B15: If Discount is applicable | C15: Total value of discount for an item | D15: Decimal(15, 2) | E15: 500
A16: GST Rate | B16: Yes | C16: GST Tax Rate | D16: Decimal(15, 2) | E16: 9
A17: Item Taxable Value | B17: Yes | C17: Taxable value of Goods or Service as per invoice | D17: Decimal(15, 2) | E17: 35500
A18: CGST Rate | B18: Yes if applicable | C18: CGST Tax Rate (Enter rate values without percentage % sign, for example if rate is 9% then enter 9 only. Also if effective GST Rate is 18 then you need to provided only 9 for CGST and 9 for SGST to make effective rate as 18) | D18: Decimal(15, 2) | E18: 9
A19: CGST Amount | B19: Yes if applicable | C19: CGST Amount | D19: Decimal(15, 2) | E19: 3195
A20: SGST Rate | B20: Yes if applicable | C20: SGST or UTGST Tax Rate (Enter rate values without percentage % sign, for example if rate is 9% then enter 9 only. Also if effective GST Rate is 18 then you need to provided only 9 for CGST and 9 for SGST to make effective rate as 18) | D20: Decimal(15, 2) | E20: 9
A21: SGST Amount | B21: Yes if applicable | C21: SGST or UTGST Amount | D21: Decimal(15, 2) | E21: 3195
A22: IGST Rate | B22: Yes if applicable | C22: IGST Tax Rate (Enter rate values without percentage % sign, for example if rate is 18% then enter 18 only) | D22: Decimal(15, 2) | E22: 18
A23: IGST Amount | B23: Yes if applicable | C23: IGST Amount | D23: Decimal(15, 2) | E23: 6390
A24: CESS Rate | B24: Yes if applicable | C24: CESS Tax Rate (Enter rate values without percentage % sign, for example if rate is 2% then enter 2 only) | D24: Decimal(15, 2) | E24: 2
A25: CESS Amount | B25: Yes if applicable | C25: CESS Amount | D25: Decimal(15, 2) | E25: 710
A26: Credit/Debit Note Date | B26: Yes, for CDNs | C26: Credit Note/Debit Note Date | D26: String (dd-MM-yyyy) | E26: 23-09-2019
A27: Credit/Debit Note Number | B27: Yes, for CDNs | C27: Credit note number-number issued | D27: Alphanumeric (Max length:16) | E27: CN1201
A28: Credit(C)/ Debit(D) Note Type | B28: Yes, for CDNs | C28: Identifies if it is a credit note or debit note | D28: C/D | E28: C
A29: Reason for issuing CDN | B29: Optional | C29: Reasons for issuing CDN: Post sale discount Deficiency in service Correction in invoice Change in POS Finalization of Provisional assessment Others | E29: Post sale discount
A30: Is this note for a Pre-GST Invoice? | B30: Yes if applicable | C30: Indicates if this document is Pre-GST or not | D30: String | E30: Y
A31: Is this a Bill of Supply | B31: If this is a bill of supply | C31: Indicates if this is a bill of supply | D31: Character | E31: Y
A32: Is Reverse Charge Applicable? | B32: Yes,If Reverse Charge is applicable | C32: Indicate if supply attracts reverse charge (Enter value as Y if reverse charge applicable otherwise leave blank) | D32: Character | E32: Y
A33: Is this a Nil Rated/Exempt/NonGST item? | B33: Yes in cases of Nil rated, Exempt, NonGST supplies | C33: If the goods or services is Nil Rated, Exempted or NonGST supply | D33: String (Max length:20) | E33: Nil rated
A34: Original Document Date (In case of amendment) | B34: Yes in case of amendments | C34: Original document date | D34: string (DD-MM-YYYY) | E34: 42403 | F34: If the invoice/bill of entry details furnished in earlier return period were incorrect then it can be corrected during current return as Amendments by providing details of original document
A35: Original Document Number (In case of amendment) | B35: Yes in case of amendments | C35: Original document number | D35: Alphanumeric (Max length:16) | E35: S008400
A36: Original Customer Billing GSTIN (In case of amendment) | B36: Yes in case of amendments for B2B Invoice | C36: GSTIN of Recipient in Original Invoice | D36: Alphanumeric with 15 characters | E36: 06ADECO9084R5Z4
A37: Date of Linked Advance Receipt | B37: Yes if Advance Receipt under reverse charge filed in previous return is adjusted against Invoice furnished in current return | C37: Date of advance receipt voucher | D37: String (DD-MM-YYYY) | E37: 42930
A38: Voucher Number of Linked Advance Receipt | B38: Yes if Advance Receipt under reverse charge filed in previous return is adjusted against Invoice furnished in current return | C38: Voucher number of advance receipt | D38: Alphanumeric (Max length:16) | E38: AR2300
A39: Adjustment Amount of Linked Advance Receipt | B39: Yes if Advance Receipt under reverse charge filed in previous return is adjusted against Invoice furnished in current return | C39: Amount of advance receipt amount to be adjusted | D39: Decimal(15, 2) | E39: 2000
A40: Type of Export | B40: Yes in case of exports | C40: Provide one of the following 5 values: Deemed Export SEZ with payment of GST SEZ without payment of GST Export with payment of GST Export without payment of GST | D40: String (Max length:90) | E40: Deemed export
...

Sheet Start
B5: Sales Invoices & Credit/Debit Notes Input file
B7: How will this Excel file help you in filing GST Returns?
B8: Using this Excel, you can enter all your Sales Invoice & Credit/Debit notes while you are offline. Once you are ready to start filing, you can upload this file on ClearTax GST Software using Cleartax Lite template. You can use the same data to prepare both GSTR-3B and GSTR-1 Returns on ClearTax. The same file can also be used to prepare ANX-1 under the new GST returns.
B9: Before filing return, you can keep updating this data in the excel sheet and re-upload your transactions as many times as you want
B11: How should I use this Excel file?
B12: STEP 1: | C12: Enter all your Sales invoice data here
C13: Enter all your Credit/Debit note data here
B15: STEP 2: | C15: Upload this Excel file by logging into your account on https://gst.cleartax.in and going to Returns Page
C17: =HYPERLINK("https://gst.cleartax.in/","Go to GST Software") -> Go to GST Software

Sheet State Code Definition
A1: State | B1: State Name | C1: 2 digit code | D1: ISO Code | E1: ISO Code Synonym | F1: State Code | G1: Synonym 1 | H1: Synonmy 2 | I1: Synonym 3 | J1: Synonym 4 | K1: Synonym 5 | L1: Synonym 6 | M1: Synonym 7 | N1: Synonym 8 | O1: Synonym 9 | P1: Synonym 10 | Q1: Synonym 11
A2: Andaman and Nicobar Islands | B2: Andaman and Nicobar Islands | C2: 35 | D2: IN-AN | E2: =HYPERLINK("http://in.an/","IN.AN") -> IN.AN | F2: AN | M2: Andaman & Nicobar Islands | N2: Andaman Nicobar Islands | O2: AndamanNicobarIslands | P2: AndamanNicobar | Q2: 35-Andaman & Nicobar Islands
A3: Andhra Pradesh | B3: Andhra Pradesh | C3: 37 | D3: IN-AP | E3: =HYPERLINK("http://in.ap/","IN.AP") -> IN.AP | F3: AP | O3: AndhraPradesh | P3: Andhra | Q3: 37-Andhra Pradesh
A4: Arunachal Pradesh | B4: Arunachal Pradesh | C4: 12 | D4: IN-AR | E4: =HYPERLINK("http://in.ar/","IN.AR") -> IN.AR | F4: AR | Q4: 12-Arunachal Pradesh
A5: Assam | B5: Assam | C5: 18 | D5: IN-AS | E5: =HYPERLINK("http://in.as/","IN.AS") -> IN.AS | F5: AS | Q5: 18-Assam
A6: Bihar | B6: Bihar | C6: 10 | D6: IN-BR | E6: =HYPERLINK("http://in.br/","IN.BR") -> IN.BR | F6: BR | Q6: 10-Bihar
A7: Chandigarh | B7: Chandigarh | C7: 04 | D7: IN-CH | E7: =HYPERLINK("http://in.ch/","IN.CH") -> IN.CH | F7: CH | G7: CHD | H7: IN-CHD | I7: IN.CHD | Q7: 04-Chandigarh
A8: Chhattisgarh | B8: Chhattisgarh | C8: 22 | D8: IN-CT | E8: =HYPERLINK("http://in.ct/","IN.CT") -> IN.CT | F8: CT | G8: CG | H8: IN-CG | I8: =HYPERLINK("http://in.cg/","IN.CG") -> IN.CG | Q8: 22-Chhattisgarh
A9: Dadra & Nagar Haveli & Daman & Diu | B9: Dadra & Nagar Haveli & Daman & Diu | C9: 26 | D9: IN-DN | E9: =HYPERLINK("http://in.dn/","IN.DN") -> IN.DN | Q9: 26-Dadra & Nagar Haveli & Daman & Diu
A10: Delhi | B10: Delhi | C10: 07 | D10: IN-DL | E10: =HYPERLINK("http://in.dl/","IN.DL") -> IN.DL | F10: DL | Q10: 07-Delhi
A11: Goa | B11: Goa | C11: 30 | D11: IN-GA | E11: =HYPERLINK("http://in.ga/","IN.GA") -> IN.GA | F11: GA | Q11: 30-Goa
A12: Gujarat | B12: Gujarat | C12: 24 | D12: IN-GJ | E12: =HYPERLINK("http://in.gj/","IN.GJ") -> IN.GJ | F12: GJ | G12: GUJ | H12: IN-GUJ | I12: IN.GUJ | Q12: 24-Gujarat
A13: Haryana | B13: Haryana | C13: 06 | D13: IN-HR | E13: =HYPERLINK("http://in.hr/","IN.HR") -> IN.HR | F13: HR | Q13: 06-Haryana
A14: Himachal Pradesh | B14: Himachal Pradesh | C14: 02 | D14: IN-HP | E14: =HYPERLINK("http://in.hp/","IN.HP") -> IN.HP | F14: HP | O14: HimachalPradesh | P14: Himachal | Q14: 02-Himachal Pradesh
A15: Jammu and Kashmir | B15: Jammu and Kashmir | C15: 01 | D15: IN-JK | E15: =HYPERLINK("http://in.jk/","IN.JK") -> IN.JK | F15: JK | M15: Jammu & Kashmir | O15: JammuKashmir | P15: Jammu | Q15: 01-Jammu & Kashmir
A16: Jharkhand | B16: Jharkhand | C16: 20 | D16: IN-JH | E16: =HYPERLINK("http://in.jh/","IN.JH") -> IN.JH | F16: JH | Q16: 20-Jharkhand
A17: Karnataka | B17: Karnataka | C17: 29 | D17: IN-KA | E17: =HYPERLINK("http://in.ka/","IN.KA") -> IN.KA | F17: KA | G17: KRN | H17: IN-KRN | I17: IN.KRN | Q17: 29-Karnataka
A18: Kerala | B18: Kerala | C18: 32 | D18: IN-KL | E18: =HYPERLINK("http://in.kl/","IN.KL") -> IN.KL | F18: KL | G18: KER | H18: IN-KER | I18: IN.KER | Q18: 32-Kerala
A19: Lakshadweep | B19: Lakshadweep | C19: 31 | D19: IN-LD | E19: =HYPERLINK("http://in.ld/","IN.LD") -> IN.LD | F19: LD | G19: LKP | Q19: 31-Lakshdweep
A20: Madhya Pradesh | B20: Madhya Pradesh | C20: 23 | D20: IN-MP | E20: =HYPERLINK("http://in.mp/","IN.MP") -> IN.MP | F20: MP | O20: MadhyaPradesh | Q20: 23-Madhya Pradesh
A21: Maharashtra | B21: Maharashtra | C21: 27 | D21: IN-MH | E21: =HYPERLINK("http://in.mh/","IN.MH") -> IN.MH | F21: MH | G21: MAH | H21: IN-MAH | I21: IN.MAH | Q21: 27-Maharashtra
A22: Manipur | B22: Manipur | C22: 14 | D22: IN-MN | E22: =HYPERLINK("http://in.mn/","IN.MN") -> IN.MN | F22: MN | G22: MNP | H22: IN-MNP | I22: IN.MNP | Q22: 14-Manipur
A23: Meghalaya | B23: Meghalaya | C23: 17 | D23: IN-ML | E23: =HYPERLINK("http://in.ml/","IN.ML") -> IN.ML | F23: ML | G23: MEG | H23: IN-MEG | I23: IN.MEG | Q23: 17-Meghalaya
A24: Mizoram | B24: Mizoram | C24: 15 | D24: IN-MZ | E24: =HYPERLINK("http://in.mz/","IN.MZ") -> IN.MZ | F24: MZ | G24: MIZ | H24: IN-MIZ | I24: IN.MIZ | Q24: 15-Mizoram
A25: Nagaland | B25: Nagaland | C25: 13 | D25: IN-NL | E25: =HYPERLINK("http://in.nl/","IN.NL") -> IN.NL | F25: NL | G25: NLD | H25: IN-NLD | I25: IN.NLD | Q25: 13-Nagaland
A26: Odisha | B26: Odisha | C26: 21 | D26: IN-OR | E26: =HYPERLINK("http://in.or/","IN.OR") -> IN.OR | F26: OR | G26: OD | H26: IN-OD | I26: =HYPERLINK("http://in.od/","IN.OD") -> IN.OD | M26: Orissa | Q26: 21-Odisha
A27: Puducherry | B27: Puducherry | C27: 34 | D27: IN-PY | E27: =HYPERLINK("http://in.py/","IN.PY") -> IN.PY | F27: PY | G27: PDY | H27: IN-PDY | I27: IN.PDY | Q27: 34-Pondicherry
A28: Punjab | B28: Punjab | C28: 03 | D28: IN-PB | E28: =HYPERLINK("http://in.pb/","IN.PB") -> IN.PB | F28: PB | Q28: 03-Punjab
A29: Rajasthan | B29: Rajasthan | C29: 08 | D29: IN-RJ | E29: =HYPERLINK("http://in.rj/","IN.RJ") -> IN.RJ | F29: RJ | G29: RAJ | H29: IN-RAJ | I29: IN.RAJ | Q29: 08-Rajasthan
A30: Sikkim | B30: Sikkim | C30: 11 | D30: IN-SK | E30: =HYPERLINK("http://in.sk/","IN.SK") -> IN.SK | F30: SK | G30: SKM | H30: IN-SKM | I30: IN.SKM | Q30: 11-Sikkim
A31: Tamil Nadu | B31: Tamil Nadu | C31: 33 | D31: IN-TN | E31: =HYPERLINK("http://in.tn/","IN.TN") -> IN.TN | F31: TN | O31: TamilNadu | Q31: 33-Tamil Nadu
A32: Telangana | B32: Telangana | C32: 36 | D32: IN-TG | E32: =HYPERLINK("http://in.tg/","IN.TG") -> IN.TG | F32: TG | G32: TS | H32: IN-TS | I32: =HYPERLINK("http://in.ts/","IN.TS") -> IN.TS | Q32: 36-Telengana
A33: Tripura | B33: Tripura | C33: 16 | D33: IN-TR | E33: =HYPERLINK("http://in.tr/","IN.TR") -> IN.TR | F33: TR | G33: TRP | H33: IN-TRP | I33: IN.TRP | Q33: 16-Tripura
A34: Uttar Pradesh | B34: Uttar Pradesh | C34: 09 | D34: IN-UP | E34: =HYPERLINK("http://in.up/","IN.UP") -> IN.UP | F34: UP | O34: UttarPradesh | Q34: 09-Uttar Pradesh
A35: Uttarakhand | B35: Uttarakhand | C35: 05 | D35: IN-UT | E35: =HYPERLINK("http://in.ut/","IN.UT") -> IN.UT | F35: UT | G35: UK | H35: IN-UK | I35: =HYPERLINK("http://in.uk/","IN.UK") -> IN.UK | J35: UA | K35: IN-UA | L35: IN-UA | Q35: 05-Uttarakhand
A36: West Bengal | B36: West Bengal | C36: 19 | D36: IN-WB | E36: =HYPERLINK("http://in.wb/","IN.WB") -> IN.WB | F36: WB | Q36: 19-West Bengal
A37: Other Territory | B37: Other Territory | C37: 97 | D37: IN-OT | E37: =HYPERLINK("http://in.ot/","IN.OT") -> IN.OT | F37: OT | O37: Others | P37: Other | Q37: 98 - Other Territory
A38: Ladakh | B38: Ladakh | C38: 38 | D38: IN-LD | F38: LA | Q38: 38-Ladakh

Sheet Synonyms Bank
B1: HEADERS | C1: VALUES | D1: SYNONYMS
B2: B2CS_TYPE | C2: E | D2: e
B3: B2CS_TYPE | C3: OE | D3: oe
B4: EXEMP_DESCRIPTION_TYPE | C4: INTER_STATE_SUPPLIES_TO_REGISTERED_PERSONS | D4: inter_state_supplies_to_registered_persons
B5: EXEMP_DESCRIPTION_TYPE | C5: INTER_STATE_SUPPLIES_TO_REGISTERED_PERSONS | D5: inter state supplies to registered persons
B6: EXEMP_DESCRIPTION_TYPE | C6: INTER_STATE_SUPPLIES_TO_REGISTERED_PERSONS | D6: inter-state supplies to registered persons
B7: EXEMP_DESCRIPTION_TYPE | C7: INTER_STATE_SUPPLIES_TO_REGISTERED_PERSONS | D7: inter-state supplies to registered
B8: EXEMP_DESCRIPTION_TYPE | C8: INTRA_STATE_SUPPLIES_TO_REGISTERED_PERSONS | D8: intra_state_supplies_to_registered_persons
B9: EXEMP_DESCRIPTION_TYPE | C9: INTRA_STATE_SUPPLIES_TO_REGISTERED_PERSONS | D9: intra state supplies to registered persons
B10: EXEMP_DESCRIPTION_TYPE | C10: INTRA_STATE_SUPPLIES_TO_REGISTERED_PERSONS | D10: intra-state supplies to registered persons
B11: EXEMP_DESCRIPTION_TYPE | C11: INTRA_STATE_SUPPLIES_TO_REGISTERED_PERSONS | D11: intra-state supplies to registered
B12: EXEMP_DESCRIPTION_TYPE | C12: INTER_STATE_SUPPLIES_TO_UNREGISTERED_PERSONS | D12: inter_state_supplies_to_unregistered_persons
... B104: NATURE_OF_DOCUMENT_TYPE | C104: REVISED_INVOICE | D104: revised_invoice
B105: MONTH_TYPE | C105: 1 | D105: 1
B106: MONTH_TYPE | C106: 1 | D106: jan
B107: MONTH_TYPE | C107: 1 | D107: january
B108: MONTH_TYPE | C108: 2 | D108: 2
B109: MONTH_TYPE | C109: 2 | D109: feb
B110: MONTH_TYPE | C110: 2 | D110: feburary
B111: MONTH_TYPE | C111: 2 | D111: 44563
B112: MONTH_TYPE | C112: 2 | D112: 44593
B113: MONTH_TYPE | C113: 3 | D113: 3
B114: MONTH_TYPE | C114: 3 | D114: mar
B115: MONTH_TYPE | C115: 3 | D115: march
B116: MONTH_TYPE | C116: 3 | D116: 44564
B117: MONTH_TYPE | C117: 3 | D117: 44621
B118: MONTH_TYPE | C118: 4 | D118: 4
B119: MONTH_TYPE | C119: 4 | D119: apr
B120: MONTH_TYPE | C120: 4 | D120: april
B121: MONTH_TYPE | C121: 4 | D121: 44565
B122: MONTH_TYPE | C122: 4 | D122: 44652
B123: MONTH_TYPE | C123: 5 | D123: 5
B124: MONTH_TYPE | C124: 5 | D124: may
B125: MONTH_TYPE | C125: 5 | D125: may
B126: MONTH_TYPE | C126: 5 | D126: 44566
B127: MONTH_TYPE | C127: 5 | D127: 44682
B128: MONTH_TYPE | C128: 6 | D128: 6
B129: MONTH_TYPE | C129: 6 | D129: jun
B130: MONTH_TYPE | C130: 6 | D130: june
B131: MONTH_TYPE | C131: 6 | D131: 44567
...

Sheet Sheet1
A1: BOOLEAN_TYPE | B1: =TRUE() -> TRUE | C1: yes | F1: CUSTOM_HEADERS
A2: BOOLEAN_TYPE | B2: =FALSE() -> FALSE | C2: no
A3: BOOLEAN_TYPE | B3: =TRUE() -> TRUE | C3: y | F3: System Header | G3: User Header
A4: BOOLEAN_TYPE | B4: =FALSE() -> FALSE | C4: n | F4: Document_Type | G4: Document Type Code *
A5: BOOLEAN_TYPE | B5: =TRUE() -> TRUE | C5: =TRUE() -> TRUE | F5: Document_Type | G5: Document Type Code
A6: BOOLEAN_TYPE | B6: =FALSE() -> FALSE | C6: =FALSE() -> FALSE | F6: Document_Type | G6: Document Type
A7: BOOLEAN_TYPE | B7: =TRUE() -> TRUE | C7: 1 | F7: Document_Type | G7: Document Type *
A8: BOOLEAN_TYPE | B8: =FALSE() -> FALSE | C8: 0 | F8: Document_Type | G8: DocumentType
F9: Document_Type | G9: Document_Type
F10: Document_Type | G10: DOCTYPE
F11: Document_Type | G11: DOC type
F12: Document_Type | G12: Document_type_code
F13: Document_Type | G13: DocumentTypeCode
F14: Document_Type | G14: DOC_TYPE
F15: Document_Type | G15: Transaction Type
F16: Document_Type | G16: DTYP
F17: Document_Type | G17: Doc type Desc
F18: Document_Type | G18: TRN_CODE
F19: Document_Type | G19: InvType
F20: Document_Type | G20: Invoice Type NIC
... F2018: Supply_Type | G2018: <PRE>\Supply Type Code\

Sheet Sheet3
A1: CUSTOM HEADERS
A2: System Header | B2: User Header
A3: Document Type Code | B3: Document Type Code *
A4: Document Type Code | B4: Document Type Code
A5: Document Type Code | B5: Document Type
A6: Document Type Code | B6: Document Type *
A7: Document Type Code | B7: DocumentType
A8: Document Type Code | B8: Document_Type
A9: Document Type Code | B9: DOCTYPE
A10: Document Type Code | B10: DOC type
A11: Document Type Code | B11: Document_type_code
A12: Document Type Code | B12: DocumentTypeCode
A13: Document Type Code | B13: DOC_TYPE
... A642: Quantity | B642: FI Qty

Sheet Units
A1: 3 DIGIT CODE | B1: EXPLANATION
A2: BAG | B2: BAG
A3: BGS | B3: BAGS
A4: BLS | B4: BAILS
A5: BTL | B5: BOTTLES
A6: BOU | B6: BOU
A7: BOX | B7: BOXES
A8: BKL | B8: BUCKLES
A9: BLK | B9: BULK
A10: BUN | B10: BUNCHES
A11: BDL | B11: BUNDLES
A12: CAN | B12: CANS
... A86: LTR | B86: LITERS

Sheet Port code
A1: Reference | B1: https://einvoice1.gst.gov.in/Others/MasterCodes
A3: S.No | B3: Location Code | C3: Location Desc. | D3: Country Code | E3: State
B4: INABG1 | C4: Alibag | D4: IN | E4: Maharashtra
B5: INACH1 | C5: Achra | D5: IN | E5: Maharashtra
B6: INADA6 | C6: Ahmedabad Adalaj | D6: IN | E6: Gujarat
B7: INADI1 | C7: Androth Island | D7: IN | E7: Lakshadweep
B8: INAGI1 | C8: Agatti Island | D8: IN | E8: Lakshadweep
B9: INAGR4 | C9: Agra | D9: IN | E9: Uttar Pradesh
B10: INAGR5 | C10: FPO AGRA | D10: IN
B11: INAGR6 | C11: Agra | D11: IN
B12: INAGTB | C12: Agartala | D12: IN | E12: Tripura
B13: INAGX4 | C13: Agatti Island | D13: IN
B14: INAHD6 | C14: ICD SANAND | D14: IN
B15: INAIG6 | C15: GE PVT. LTD. | D15: IN | E15: Maharashtra
B16: INAII6 | C16: M/S IGATE GS LTD. | D16: IN
B17: INAIK6 | C17: IBRAHIMPURICD KHURJA | D17: IN
B18: INAIR6 | C18: SP PVT. LTD. | D18: IN | E18: Maharashtra
B19: INAJE6 | C19: WLSPUN ANJAR SEZ | D19: IN | E19: Gujarat
B20: INAJJ6 | C20: Arakkonam Melpakkam | D20: IN | E20: Tamil Nadu
B21: INAJL4 | C21: Aizawl | D21: IN
B22: INAJM6 | C22: MUNDRA PORT SEZ | D22: IN | E22: Gujarat
B23: INAKB6 | C23: BIACPL SEZ | D23: IN | E23: Andhra Pradesh
B24: INAKD4 | C24: Akola | D24: IN
B25: INAKP6 | C25: APIICL SEZ | D25: IN | E25: Andhra Pradesh
B26: INAKR6 | C26: RPCIPL SEZ | D26: IN | E26: Andhra Pradesh
B27: INAKV6 | C27: Ankleshwar ICD | D27: IN | E27: Gujarat
B28: INALA1 | C28: ALANG SBY | D28: IN | E28: Gujarat
B29: INALF1 | C29: Allepey | D29: IN | E29: Kerala
B30: INAMD4 | C30: Ahmedabad | D30: IN | E30: Gujarat
B31: INAMD5 | C31: Ahmedabad | D31: IN | E31: Gujarat
B32: INAMD6 | C32: Ahmedabad | D32: IN
B33: INAMG6 | C33: Amingaon (Gauhati) | D33: IN | E33: Assam
B34: INAMI1 | C34: Amini Island | D34: IN | E34: Lakshadweep
B35: INAMK6 | C35: KSITIL/SEZ/ALAPPUZHA | D35: IN
B36: INANG1 | C36: Anijengo | D36: IN | E36: Kerala
B37: INANL1 | C37: Arnala | D37: IN | E37: Maharashtra
B38: INAPI6 | C38: AAP-SEZ AHMEDABAD | D38: IN | E38: Gujarat
B39: INAPL6 | C39: Dadri ACPL CFS | D39: IN | E39: Uttar Pradesh
B40: INAPT6 | C40: Anaparti | D40: IN | E40: Andhra Pradesh
B41: INARR6 | C41: Aroor | D41: IN | E41: Kerala
...

Sheet Data Validation
A1: Item_Category | B1: Input Type | C1: Flag_Reverse_Charge | D1: GST return quarter | E1: Flag_Import_Invoice | F1: GST return period | G1: Export_Category_Type | I1: Flag_if_GST_TDS_deducted | J1: Credit(C)/ Debit(D) Note Type | K1: ITC_Availability_type | L1: Reason for issuing CDN | M1: Type_Nil_Exempt_NonGST | N1: Type of Supplier | O1: IGST Rate | P1: CGST SGST rate | R1: BAG-BAGS | T1: State code and state | V1: Document Type Code | W1: Supply Type Code | Y1: 42917 | Z1: GST return period | AA1: Quarter | AB1: GST return period | AD1: Port code | AG1: Supplies u/s 9(5) | AI1: Which type of Invoice is this note linked to? | AJ1: Special validations (For Multiple amendments, B2C to B2B conversion, etc.) | AL1: Deleted | AM1: Return Type | AN1: Sub Type
A2: G | B2: EXCLUSIVELY - NON BUSINESS | C2: Y | D2: =IF(Y2<2017,"","Jan-Mar "&Y2) -> Jan-Mar 2025 | E2: Y | F2: =IF(EOMONTH(TODAY(),AB2)+1<$Y$1,"",EOMONTH(TODAY(),AB2)+1) -> 45901 | G2: Deemed Export | I2: Y | J2: C | K2: Input | L2: Sales Return | M2: Nil rated | N2: Composition | O2: 0 | P2: =O2/2 -> 0 | R2: BAL-BALE | T2: 01-Jammu & Kashmir | V2: Invoice | W2: B2B | Y2: =YEAR(TODAY()) -> 2025 | Z2: -1 | AA2: =YEAR(TODAY()) -> 2025 | AB2: -1 | AD2: ='Port code'!B4&"-"&'Port code'!C4 -> INABG1-Alibag | AG2: 3.1.1(i) Furnished by ECO | AI2: B2CL | AJ2: Multiple Amendments | AL2: Y | AM2: GSTR1 | AN2: Supply
A3: S | B3: EXCLUSIVELY - USED FOR EXEMPT SUPPLIES | D3: =IF(Y3<2017,"","Apr-Jun "&Y3) -> Apr-Jun 2025 | F3: =IF(EOMONTH(TODAY(),AB3)+1<$Y$1,"",EOMONTH(TODAY(),AB3)+1) -> 45870 | G3: SEZ with payment of GST | J3: D | K3: Input Service | L3: Post sale discount | M3: Exempt | O3: 0.1 | P3: 0.05 | R3: BDL-BUNDLES | T3: 02-Himachal Pradesh | V3: Credit Note | W3: B2BA | Y3: =YEAR(TODAY()) -> 2025 | Z3: -2 | AA3: =YEAR(TODAY()) -> 2025 | AB3: -2 | AD3: ='Port code'!B5&"-"&'Port code'!C5 -> INACH1-Achra | AG3: 3.1.1(ii) Furnished by person making supplies through ECO | AI3: B2CS | AJ3: B2Cs Amendment (B2Cs to B2B) | AM3: GSTR1A | AN3: Job Work
B4: DISALLOWED - U/S 17(5) | D4: =IF(Y4<2017,"","Jul-Sep "&Y4) -> Jul-Sep 2025 | F4: =IF(EOMONTH(TODAY(),AB4)+1<$Y$1,"",EOMONTH(TODAY(),AB4)+1) -> 45839 | G4: SEZ without payment of GST | K4: Capital Good | L4: Deficiency in service | M4: NonGST | O4: 0.25 | P4: =O4/2 -> 0.125 | R4: BKL-BUCKLES | T4: 03-Punjab | V4: Debit Note | W4: SEZWOP | Y4: =YEAR(TODAY()) -> 2025 | Z4: -3 | AA4: =YEAR(TODAY()) -> 2025 | AB4: -3 | AD4: ='Port code'!B6&"-"&'Port code'!C6 -> INADA6-Ahmedabad Adalaj | AN4: SKD/CKD
B5: EXCLUSIVELY - EXCEPT EXEMPT (INCL. ZERO RATED) | D5: =IF(Y5<2017,"","Oct-Dec "&Y5) -> Oct-Dec 2025 | F5: =IF(EOMONTH(TODAY(),AB5)+1<$Y$1,"",EOMONTH(TODAY(),AB5)+1) -> 45809 | G5: Export with payment of GST | K5: Ineligible | L5: Correction in invoice | O5: 1 | P5: =O5/2 -> 0.5 | R5: BOU-BILLION OF UNITS | T5: 04-Chandigarh | V5: Advance | W5: SEZWP | Y5: =YEAR(TODAY()) -> 2025 | Z5: -4 | AA5: =YEAR(TODAY()) -> 2025 | AB5: -4 | AD5: ='Port code'!B7&"-"&'Port code'!C7 -> INADI1-Androth Island | AN5: Recipient Not Known
B6: COMMON CREDIT - PARTLY FOR BUSINESS AND PARTLY NON BUSINESS | D6: =IF(Y6<2017,"","Jan-Mar "&Y6) -> Jan-Mar 2024 | F6: =IF(EOMONTH(TODAY(),AB6)+1<$Y$1,"",EOMONTH(TODAY(),AB6)+1) -> 45778 | G6: Export without payment of GST | K6: None | L6: Change in POS | O6: 1.5 | P6: =O6/2 -> 0.75 | R6: BOX-BOX | T6: 05-Uttarakhand | V6: Advance Adjustment | W6: DEXP | Y6: =Y2-1 -> 2024 | Z6: -5 | AA6: =AA2-1 -> 2024 | AB6: -5 | AD6: ='Port code'!B8&"-"&'Port code'!C8 -> INAGI1-Agatti Island | AN6: For Own Use
D7: =IF(Y7<2017,"","Apr-Jun "&Y7) -> Apr-Jun 2024 | F7: =IF(EOMONTH(TODAY(),AB7)+1<$Y$1,"",EOMONTH(TODAY(),AB7)+1) -> 45748 | G7: Intra-State supplies attracting IGST | L7: Finalization of Provisional assessment | O7: 3 | P7: =O7/2 -> 1.5 | R7: BTL-BOTTLES | T7: 06-Haryana | V7: Challan | W7: Intra-state supplies attracting IGST | Y7: =Y3-1 -> 2024 | Z7: -6 | AA7: =AA3-1 -> 2024 | AB7: -6 | AD7: ='Port code'!B9&"-"&'Port code'!C9 -> INAGR4-Agra | AN7: Exhibition or Fairs
D8: =IF(Y8<2017,"","Jul-Sep "&Y8) -> Jul-Sep 2024 | F8: =IF(EOMONTH(TODAY(),AB8)+1<$Y$1,"",EOMONTH(TODAY(),AB8)+1) -> 45717 | L8: Others | O8: 5 | P8: =O8/2 -> 2.5 | R8: BUN-BUNCHES | T8: 07-Delhi | W8: B2CS | Y8: =Y4-1 -> 2024 | Z8: -7 | AA8: =AA4-1 -> 2024 | AB8: -7 | AD8: ='Port code'!B10&"-"&'Port code'!C10 -> INAGR5-FPO AGRA | AN8: Lines Sales
D9: =IF(Y9<2017,"","Oct-Dec "&Y9) -> Oct-Dec 2024 | F9: =IF(EOMONTH(TODAY(),AB9)+1<$Y$1,"",EOMONTH(TODAY(),AB9)+1) -> 45689 | O9: 7.5 | P9: =O9/2 -> 3.75 | R9: CAN-CANS | T9: 08-Rajasthan | W9: B2CSA | Y9: =Y5-1 -> 2024 | Z9: -8 | AA9: =AA5-1 -> 2024 | AB9: -8 | AD9: ='Port code'!B11&"-"&'Port code'!C11 -> INAGR6-Agra | AN9: Others
D10: =IF(Y10<2017,"","Jan-Mar "&Y10) -> Jan-Mar 2023 | F10: =IF(EOMONTH(TODAY(),AB10)+1<$Y$1,"",EOMONTH(TODAY(),AB10)+1) -> 45658 | O10: 12 | P10: =O10/2 -> 6 | R10: CBM-CUBIC METERS | T10: 09-Uttar Pradesh | W10: B2CL | Y10: =Y6-1 -> 2023 | Z10: -9 | AA10: =AA6-1 -> 2023 | AB10: -9 | AD10: ='Port code'!B12&"-"&'Port code'!C12 -> INAGTB-Agartala | AN10: Job work Returns
D11: =IF(Y11<2017,"","Apr-Jun "&Y11) -> Apr-Jun 2023 | F11: =IF(EOMONTH(TODAY(),AB11)+1<$Y$1,"",EOMONTH(TODAY(),AB11)+1) -> 45627 | I11: Invoice Type | J11: Voucher type | K11: Type of supply | O11: 18 | P11: =O11/2 -> 9 | R11: CCM-CUBIC CENTIMETERS | T11: 10-Bihar | W11: B2CLA | Y11: =Y7-1 -> 2023 | Z11: -10 | AA11: =AA7-1 -> 2023 | AB11: -10 | AD11: ='Port code'!B13&"-"&'Port code'!C13 -> INAGX4-Agatti Island | AN11: Sales Return
D12: =IF(Y12<2017,"","Jul-Sep "&Y12) -> Jul-Sep 2023 | F12: =IF(EOMONTH(TODAY(),AB12)+1<$Y$1,"",EOMONTH(TODAY(),AB12)+1) -> 45597 | I12: Regular | J12: Refund voucher | K12: Inter | L12: Pre GST (only in case of Cr/Dr Note) | O12: 28 | P12: =O12/2 -> 14 | R12: CMS-CENTIMETERS | T12: 11-Sikkim | W12: EXPWOP | Y12: =Y8-1 -> 2023 | Z12: -11 | AA12: =AA8-1 -> 2023 | AB12: -11 | AD12: ='Port code'!B14&"-"&'Port code'!C14 -> INAHD6-ICD SANAND
D13: =IF(Y13<2017,"","Oct-Dec "&Y13) -> Oct-Dec 2023 | F13: =IF(EOMONTH(TODAY(),AB13)+1<$Y$1,"",EOMONTH(TODAY(),AB13)+1) -> 45566 | G13: 65 | I13: SEZ WO Payment | J13: Advance voucher | K13: Intra | L13: Y | O13: 40 | P13: 20 | R13: CTN-CARTONS | T13: 12-Arunachal Pradesh | W13: EXPWP | Y13: =Y9-1 -> 2023 | Z13: -12 | AA13: =AA9-1 -> 2023 | AB13: -12 | AD13: ='Port code'!B15&"-"&'Port code'!C15 -> INAIG6-GE PVT. LTD.
D14: =IF(Y14<2017,"","Jan-Mar "&Y14) -> Jan-Mar 2022 | F14: =IF(EOMONTH(TODAY(),AB14)+1<$Y$1,"",EOMONTH(TODAY(),AB14)+1) -> 45536 | I14: SEZ W Payment | L14: N | R14: DOZ-DOZENS | T14: 13-Nagaland | V14: Composition | W14: EXPA | Y14: =Y10-1 -> 2022 | Z14: -13 | AA14: =AA10-1 -> 2022 | AB14: -13 | AD14: ='Port code'!B16&"-"&'Port code'!C16 -> INAII6-M/S IGATE GS LTD.
D15: =IF(Y15<2017,"","Apr-Jun "&Y15) -> Apr-Jun 2022 | F15: =IF(EOMONTH(TODAY(),AB15)+1<$Y$1,"",EOMONTH(TODAY(),AB15)+1) -> 45505 | I15: Deemed Exp | R15: DRM-DRUMS | T15: 14-Manipur | V15: UIN | W15: CDNR | Y15: =Y11-1 -> 2022 | Z15: -14 | AA15: =AA11-1 -> 2022 | AB15: -14 | AD15: ='Port code'!B17&"-"&'Port code'!C17 -> INAIK6-IBRAHIMPURICD KHURJA
D16: =IF(Y16<2017,"","Jul-Sep "&Y16) -> Jul-Sep 2022 | F16: =IF(EOMONTH(TODAY(),AB16)+1<$Y$1,"",EOMONTH(TODAY(),AB16)+1) -> 45474 | R16: GGK-GREAT GROSS | T16: 15-Mizoram | W16: CDNRA | Y16: =Y12-1 -> 2022 | Z16: -15 | AA16: =AA12-1 -> 2022 | AB16: -15 | AD16: ='Port code'!B18&"-"&'Port code'!C18 -> INAIR6-SP PVT. LTD.
D17: =IF(Y17<2017,"","Oct-Dec "&Y17) -> Oct-Dec 2022 | F17: =IF(EOMONTH(TODAY(),AB17)+1<$Y$1,"",EOMONTH(TODAY(),AB17)+1) -> 45444 | R17: GMS-GRAMMES | T17: 16-Tripura | W17: CDNUR | Y17: =Y13-1 -> 2022 | Z17: -16 | AA17: =AA13-1 -> 2022 | AB17: -16 | AD17: ='Port code'!B19&"-"&'Port code'!C19 -> INAJE6-WLSPUN ANJAR SEZ
D18: =IF(Y18<2017,"","Jan-Mar "&Y18) -> Jan-Mar 2021 | F18: =IF(EOMONTH(TODAY(),AB18)+1<$Y$1,"",EOMONTH(TODAY(),AB18)+1) -> 45413 | R18: GRS-GROSS | T18: 17-Meghalaya | W18: CDNURA | Y18: =Y14-1 -> 2021 | Z18: -17 | AA18: =AA14-1 -> 2021 | AB18: -17 | AD18: ='Port code'!B20&"-"&'Port code'!C20 -> INAJJ6-Arakkonam Melpakkam
D19: =IF(Y19<2017,"","Apr-Jun "&Y19) -> Apr-Jun 2021 | F19: =IF(EOMONTH(TODAY(),AB19)+1<$Y$1,"",EOMONTH(TODAY(),AB19)+1) -> 45383 | R19: GYD-GROSS YARDS | T19: 18-Assam | W19: Nil Rated | Y19: =Y15-1 -> 2021 | Z19: -18 | AA19: =AA15-1 -> 2021 | AB19: -18 | AD19: ='Port code'!B21&"-"&'Port code'!C21 -> INAJL4-Aizawl
D20: =IF(Y20<2017,"","Jul-Sep "&Y20) -> Jul-Sep 2021 | F20: =IF(EOMONTH(TODAY(),AB20)+1<$Y$1,"",EOMONTH(TODAY(),AB20)+1) -> 45352 | R20: KGS-KILOGRAMS | T20: 19-West Bengal | W20: Non GST | Y20: =Y16-1 -> 2021 | Z20: -19 | AA20: =AA16-1 -> 2021 | AB20: -19 | AD20: ='Port code'!B22&"-"&'Port code'!C22 -> INAJM6-MUNDRA PORT SEZ
D21: =IF(Y21<2017,"","Oct-Dec "&Y21) -> Oct-Dec 2021 | F21: =IF(EOMONTH(TODAY(),AB21)+1<$Y$1,"",EOMONTH(TODAY(),AB21)+1) -> 45323 | R21: KLR-KILOLITRE | T21: 20-Jharkhand | W21: Exempted | Y21: =Y17-1 -> 2021 | Z21: -20 | AA21: =AA17-1 -> 2021 | AB21: -20 | AD21: ='Port code'!B23&"-"&'Port code'!C23 -> INAKB6-BIACPL SEZ
D22: =IF(Y22<2017,"","Jan-Mar "&Y22) -> Jan-Mar 2020 | F22: =IF(EOMONTH(TODAY(),AB22)+1<$Y$1,"",EOMONTH(TODAY(),AB22)+1) -> 45292 | R22: KME-KILOMETRE | T22: 21-Odisha | W22: BOS | Y22: =Y18-1 -> 2020 | Z22: -21 | AA22: =AA18-1 -> 2020 | AB22: -21 | AD22: ='Port code'!B24&"-"&'Port code'!C24 -> INAKD4-Akola
D23: =IF(Y23<2017,"","Apr-Jun "&Y23) -> Apr-Jun 2020 | F23: =IF(EOMONTH(TODAY(),AB23)+1<$Y$1,"",EOMONTH(TODAY(),AB23)+1) -> 45261 | R23: MLT-MILILITRE | T23: 22-Chhattisgarh | W23: AT | Y23: =Y19-1 -> 2020 | Z23: -22 | AA23: =AA19-1 -> 2020 | AB23: -22 | AD23: ='Port code'!B25&"-"&'Port code'!C25 -> INAKP6-APIICL SEZ
D24: =IF(Y24<2017,"","Jul-Sep "&Y24) -> Jul-Sep 2020 | F24: =IF(EOMONTH(TODAY(),AB24)+1<$Y$1,"",EOMONTH(TODAY(),AB24)+1) -> 45231 | R24: MTR-METERS | T24: 23-Madhya Pradesh | W24: ATA | Y24: =Y20-1 -> 2020 | Z24: -23 | AA24: =AA20-1 -> 2020 | AB24: -23 | AD24: ='Port code'!B26&"-"&'Port code'!C26 -> INAKR6-RPCIPL SEZ
D25: =IF(Y25<2017,"","Oct-Dec "&Y25) -> Oct-Dec 2020 | F25: =IF(EOMONTH(TODAY(),AB25)+1<$Y$1,"",EOMONTH(TODAY(),AB25)+1) -> 45200 | R25: MTS-METRIC TON | T25: 24-Gujarat | Y25: =Y21-1 -> 2020 | Z25: -24 | AA25: =AA21-1 -> 2020 | AB25: -24 | AD25: ='Port code'!B27&"-"&'Port code'!C27 -> INAKV6-Ankleshwar ICD
F26: =IF(EOMONTH(TODAY(),AB26)+1<$Y$1,"",EOMONTH(TODAY(),AB26)+1) -> 45170 | R26: NOS-NUMBERS | T26: 25-Daman & Diu | Y26: =Y22-1 -> 2019 | Z26: -25 | AA26: =AA22-1 -> 2019 | AB26: -25 | AD26: ='Port code'!B28&"-"&'Port code'!C28 -> INALA1-ALANG SBY
F27: =IF(EOMONTH(TODAY(),AB27)+1<$Y$1,"",EOMONTH(TODAY(),AB27)+1) -> 45139 | R27: PAC-PACKS | T27: 26-Dadra & Nagar Haveli and Daman and Diu | Y27: =Y23-1 -> 2019 | Z27: -26 | AA27: =AA23-1 -> 2019 | AB27: -26 | AD27: ='Port code'!B29&"-"&'Port code'!C29 -> INALF1-Allepey
F28: =IF(EOMONTH(TODAY(),AB28)+1<$Y$1,"",EOMONTH(TODAY(),AB28)+1) -> 45108 | R28: PCS-PIECES | T28: 27-Maharashtra | Y28: =Y24-1 -> 2019 | Z28: -27 | AA28: =AA24-1 -> 2019 | AB28: -27 | AD28: ='Port code'!B30&"-"&'Port code'!C30 -> INAMD4-Ahmedabad
F29: =IF(EOMONTH(TODAY(),AB29)+1<$Y$1,"",EOMONTH(TODAY(),AB29)+1) -> 45078 | R29: PRS-PAIRS | T29: 29-Karnataka | Y29: =Y25-1 -> 2019 | Z29: -28 | AA29: =AA25-1 -> 2019 | AB29: -28 | AD29: ='Port code'!B31&"-"&'Port code'!C31 -> INAMD5-Ahmedabad
F30: =IF(EOMONTH(TODAY(),AB30)+1<$Y$1,"",EOMONTH(TODAY(),AB30)+1) -> 45047 | R30: QTL-QUINTAL | T30: 30-Goa | Y30: =Y26-1 -> 2018 | Z30: -29 | AA30: =AA26-1 -> 2018 | AB30: -29 | AD30: ='Port code'!B32&"-"&'Port code'!C32 -> INAMD6-Ahmedabad
F31: =IF(EOMONTH(TODAY(),AB31)+1<$Y$1,"",EOMONTH(TODAY(),AB31)+1) -> 45017 | R31: ROL-ROLLS | T31: 31-Lakshadweep | Y31: =Y27-1 -> 2018 | Z31: -30 | AA31: =AA27-1 -> 2018 | AB31: -30 | AD31: ='Port code'!B33&"-"&'Port code'!C33 -> INAMG6-Amingaon (Gauhati)
F32: =IF(EOMONTH(TODAY(),AB32)+1<$Y$1,"",EOMONTH(TODAY(),AB32)+1) -> 44986 | R32: SET-SETS | T32: 32-Kerala | Y32: =Y28-1 -> 2018 | Z32: -31 | AA32: =AA28-1 -> 2018 | AB32: -31 | AD32: ='Port code'!B34&"-"&'Port code'!C34 -> INAMI1-Amini Island
F33: =IF(EOMONTH(TODAY(),AB33)+1<$Y$1,"",EOMONTH(TODAY(),AB33)+1) -> 44958 | R33: SQF-SQUARE FEET | T33: 33-Tamil Nadu | Y33: =Y29-1 -> 2018 | Z33: -32 | AA33: =AA29-1 -> 2018 | AB33: -32 | AD33: ='Port code'!B35&"-"&'Port code'!C35 -> INAMK6-KSITIL/SEZ/ALAPPUZHA
F34: =IF(EOMONTH(TODAY(),AB34)+1<$Y$1,"",EOMONTH(TODAY(),AB34)+1) -> 44927 | R34: SQM-SQUARE METERS | T34: 34-Pondicherry | Y34: =Y30-1 -> 2017 | Z34: -33 | AA34: =AA30-1 -> 2017 | AB34: -33 | AD34: ='Port code'!B36&"-"&'Port code'!C36 -> INANG1-Anijengo
F35: =IF(EOMONTH(TODAY(),AB35)+1<$Y$1,"",EOMONTH(TODAY(),AB35)+1) -> 44896 | R35: SQY-SQUARE YARDS | T35: 35-Andaman & Nicobar Islands | Y35: =Y31-1 -> 2017 | Z35: -34 | AA35: =AA31-1 -> 2017 | AB35: -34 | AD35: ='Port code'!B37&"-"&'Port code'!C37 -> INANL1-Arnala
F36: =IF(EOMONTH(TODAY(),AB36)+1<$Y$1,"",EOMONTH(TODAY(),AB36)+1) -> 44866 | R36: TBS-TABLETS | T36: 36-Telangana | Y36: =Y32-1 -> 2017 | Z36: -35 | AA36: =AA32-1 -> 2017 | AB36: -35 | AD36: ='Port code'!B38&"-"&'Port code'!C38 -> INAPI6-AAP-SEZ AHMEDABAD
F37: =IF(EOMONTH(TODAY(),AB37)+1<$Y$1,"",EOMONTH(TODAY(),AB37)+1) -> 44835 | R37: TGM-TEN GROSS | T37: 37-Andhra Pradesh | Y37: =Y33-1 -> 2017 | Z37: -36 | AA37: =AA33-1 -> 2017 | AB37: -36 | AD37: ='Port code'!B39&"-"&'Port code'!C39 -> INAPL6-Dadri ACPL CFS
R38: THD-THOUSANDS | T38: 38-Ladakh | AD38: ='Port code'!B40&"-"&'Port code'!C40 -> INAPT6-Anaparti
D39: =IF(Y39<2017,"","Jan-Mar "&Y39) | F39: =IF(EOMONTH(TODAY(),AB39)+1<$Y$1,"",EOMONTH(TODAY(),AB39)+1) -> 44805 | R39: TON-TONNES | T39: 96- Foreign Country | Y39: =Y34-1 -> 2016 | Z39: -37 | AA39: =AA34-1 -> 2016 | AB39: -37 | AD39: ='Port code'!B41&"-"&'Port code'!C41 -> INARR6-Aroor
D40: =IF(Y40<2017,"","Apr-Jun "&Y40) | F40: =IF(EOMONTH(TODAY(),AB40)+1<$Y$1,"",EOMONTH(TODAY(),AB40)+1) -> 44774 | R40: TUB-TUBES | T40: 97-Other Territory | Y40: =Y35-1 -> 2016 | Z40: -38 | AA40: =AA35-1 -> 2016 | AB40: -38 | AD40: ='Port code'!B42&"-"&'Port code'!C42 -> INASR2-Amritsar Railway Stn
...
